Workbook

Sheet Assumptions
A1: Assumptions & drivers (blue = input, black = formula)
A2: Colgrid. Casual play by default; opt-in tournament has no extra fee, so it adds no revenue line. Salt Lake pilot season, then Ogden (Chapter 02) and Provo (Chapter 03). Figures from the pricing doc dated 2026-09-27.
A4: Unit inputs
A5: Single gathering ticket price ($) | B5: 75 | C5: Pricing doc; U.S. food tours run $45-$150, most good ones $65-$89
A6: Season Pass price, 4 gatherings ($) | B6: 280 | C6: $70 per gathering
A7: Share of players on a Season Pass | B7: 0.4 | C7: Estimate; confirm in pilot
A8: Average revenue per ticketed player ($) | B8: =B5*(1-B7)+(B6/4)*B7 -> 73 | C8: Blend of single tickets and passes
A9: Direct cost per player ($) | B9: 40 | C9: Hosts $18, finale meal $12, game master $6, keepsakes $4
A10: Corporate private run price ($) | B10: 2500 | C10: Up to 20 players; national team-building hunts run $50-$150/person
A11: Corporate run direct cost ($) | B11: =960+20*16 -> 1280 | C11: $960 fixed per session + $16 per head x 20
A12: Sponsorship fulfillment cost (% of sponsor revenue) | B12: 0.1 | C12: Impact report, sponsor quest materials
A13: Flagship price per player ($) | B13: 725 | C13: 2-night retreat
A14: Flagship direct cost per player ($) | B14: 545 | C14: High end of $420-$545 estimate: lodging, meals, hosts, keepsakes
A15: Vanguard membership price ($/yr) | B15: 360 | C15: 4 gatherings in any city + guest seat + kit
A16: Vanguard direct cost per member ($) | B16: 225 | C16: 5 seats x $40 + $25 kit
A17: Card/processing fees absorbed (% of revenue) | B17: 0.015 | C17: Ticket fees passed to buyers; covers invoices and passes
A19: Monthly drivers
A20: Month # | B20: 1 | C20: 2 | D20: 3 | E20: 4 | F20: 5 | G20: 6 | H20: 7 | I20: 8 | J20: 9 | K20: 10 | L20: 11 | M20: 12 | N20: 13 | O20: 14 | P20: 15 | Q20: 16 | R20: 17 | S20: 18 | T20: 19 | U20: 20 | V20: 21 | W20: 22 | X20: 23 | Y20: 24 | Z20: Total | AA20: Notes
A21: Month | B21: =EDATE('1st Year Projections'!$A$2,0) -> 46388 | C21: =EDATE('1st Year Projections'!$A$2,1) -> 46419 | D21: =EDATE('1st Year Projections'!$A$2,2) -> 46447 | E21: =EDATE('1st Year Projections'!$A$2,3) -> 46478 | F21: =EDATE('1st Year Projections'!$A$2,4) -> 46508 | G21: =EDATE('1st Year Projections'!$A$2,5) -> 46539 | H21: =EDATE('1st Year Projections'!$A$2,6) -> 46569 | I21: =EDATE('1st Year Projections'!$A$2,7) -> 46600 | J21: =EDATE('1st Year Projections'!$A$2,8) -> 46631 | K21: =EDATE('1st Year Projections'!$A$2,9) -> 46661 | L21: =EDATE('1st Year Projections'!$A$2,10) -> 46692 | M21: =EDATE('1st Year Projections'!$A$2,11) -> 46722 | N21: =EDATE('1st Year Projections'!$A$2,12) -> 46753 | O21: =EDATE('1st Year Projections'!$A$2,13) -> 46784 | P21: =EDATE('1st Year Projections'!$A$2,14) -> 46813 | Q21: =EDATE('1st Year Projections'!$A$2,15) -> 46844 | R21: =EDATE('1st Year Projections'!$A$2,16) -> 46874 | S21: =EDATE('1st Year Projections'!$A$2,17) -> 46905 | T21: =EDATE('1st Year Projections'!$A$2,18) -> 46935 | U21: =EDATE('1st Year Projections'!$A$2,19) -> 46966 | V21: =EDATE('1st Year Projections'!$A$2,20) -> 46997 | W21: =EDATE('1st Year Projections'!$A$2,21) -> 47027 | X21: =EDATE('1st Year Projections'!$A$2,22) -> 47058 | Y21: =EDATE('1st Year Projections'!$A$2,23) -> 47088
A22: Salt Lake players (Chapter 01) | B22: 0 | C22: 40 | D22: 40 | E22: 40 | F22: 40 | G22: 0 | H22: 45 | I22: 45 | J22: 45 | K22: 45 | L22: 45 | M22: 0 | N22: 50 | O22: 50 | P22: 50 | Q22: 50 | R22: 50 | S22: 0 | T22: 50 | U22: 50 | V22: 50 | W22: 50 | X22: 50 | Y22: 0 | Z22: =SUM(B22:Y22) -> 885 | AA22: Pilot: 4 gatherings Feb-May at 40; Season 2 Jul-Nov at 45; year 2 at 50, off in Jun and Dec
A23: Ogden players (Chapter 02) | B23: 0 | C23: 0 | D23: 0 | E23: 0 | F23: 0 | G23: 0 | H23: 0 | I23: 0 | J23: 30 | K23: 30 | L23: 30 | M23: 30 | N23: 35 | O23: 35 | P23: 35 | Q23: 35 | R23: 35 | S23: 0 | T23: 35 | U23: 35 | V23: 35 | W23: 35 | X23: 35 | Y23: 0 | Z23: =SUM(B23:Y23) -> 470 | AA23: Opens Sep of year 1 at 30; 35 in year 2
A24: Provo players (Chapter 03) | B24: 0 | C24: 0 | D24: 0 | E24: 0 | F24: 0 | G24: 0 | H24: 0 | I24: 0 | J24: 0 | K24: 0 | L24: 0 | M24: 0 | N24: 0 | O24: 0 | P24: 0 | Q24: 0 | R24: 0 | S24: 0 | T24: 30 | U24: 30 | V24: 30 | W24: 30 | X24: 30 | Y24: 0 | Z24: =SUM(B24:Y24) -> 150 | AA24: Opens Jul of year 2 at 30
A25: Total ticketed players | B25: =SUM(B22:B24) -> 0 | C25: =SUM(C22:C24) -> 40 | D25: =SUM(D22:D24) -> 40 | E25: =SUM(E22:E24) -> 40 | F25: =SUM(F22:F24) -> 40 | G25: =SUM(G22:G24) -> 0 | H25: =SUM(H22:H24) -> 45 | I25: =SUM(I22:I24) -> 45 | ... Y25: =SUM(Y22:Y24) -> 0 | Z25: =SUM(B25:Y25) -> 1505 | AA25: Vanguard members are not counted here; their seat cost is in the membership line
A26: Corporate private runs | B26: 0 | C26: 0 | D26: 0 | E26: 0 | F26: 0 | G26: 1 | H26: 1 | I26: 1 | J26: 1 | K26: 1 | L26: 2 | M26: 2 | N26: 2 | O26: 2 | P26: 2 | Q26: 2 | R26: 2 | S26: 2 | T26: 2 | U26: 2 | V26: 2 | W26: 2 | X26: 2 | Y26: 2 | Z26: =SUM(B26:Y26) -> 33 | AA26: Start after the pilot; 2/month in year 2
A27: Sponsorship revenue ($) | B27: 0 | C27: 0 | D27: 0 | E27: 0 | F27: 0 | G27: 0 | H27: 5000 | I27: 0 | J27: 5000 | K27: 0 | L27: 0 | M27: 0 | N27: 5000 | O27: 0 | P27: 5000 | Q27: 0 | R27: 0 | S27: 0 | T27: 10000 | U27: 10000 | V27: 5000 | W27: 0 | X27: 0 | Y27: 0 | Z27: =SUM(B27:Y27) -> 45000 | AA27: BID / tourism / brand sponsors per chapter season; $10k flagship sponsor in yr 2
A28: Flagship players | B28: 0 | C28: 0 | D28: 0 | E28: 0 | F28: 0 | G28: 0 | H28: 0 | I28: 0 | J28: 0 | K28: 0 | L28: 0 | M28: 0 | N28: 0 | O28: 0 | P28: 0 | Q28: 0 | R28: 0 | S28: 0 | T28: 0 | U28: 0 | V28: 60 | W28: 0 | X28: 0 | Y28: 0 | Z28: =SUM(B28:Y28) -> 60 | AA28: First flagship in month 21 (Sep, year 2): tournament Championship qualifiers + Explorer lottery winners
A29: New Vanguard members | B29: 0 | C29: 0 | D29: 0 | E29: 0 | F29: 0 | G29: 0 | H29: 0 | I29: 0 | J29: 0 | K29: 0 | L29: 0 | M29: 0 | N29: 15 | O29: 5 | P29: 5 | Q29: 3 | R29: 3 | S29: 3 | T29: 3 | U29: 3 | V29: 3 | W29: 3 | X29: 3 | Y29: 3 | Z29: =SUM(B29:Y29) -> 52 | AA29: Membership launches in year 2, once a second city is open
A31: Revenue ($)
A32: Gathering tickets & Season Passes | B32: =B25*$B$8 -> 0 | C32: =C25*$B$8 -> 2920 | D32: =D25*$B$8 -> 2920 | E32: =E25*$B$8 -> 2920 | F32: =F25*$B$8 -> 2920 | G32: =G25*$B$8 -> 0 | H32: =H25*$B$8 -> 3285 | I32: =I25*$B$8 -> 3285 | ... Y32: =Y25*$B$8 -> 0 | Z32: =SUM(B32:Y32) -> 109865
A33: Corporate private runs | B33: =B26*$B$10 -> 0 | C33: =C26*$B$10 -> 0 | D33: =D26*$B$10 -> 0 | E33: =E26*$B$10 -> 0 | F33: =F26*$B$10 -> 0 | G33: =G26*$B$10 -> 2500 | H33: =H26*$B$10 -> 2500 | I33: =I26*$B$10 -> 2500 | ... Y33: =Y26*$B$10 -> 5000 | Z33: =SUM(B33:Y33) -> 82500
A34: Sponsorships | B34: =B27 -> 0 | C34: =C27 -> 0 | D34: =D27 -> 0 | E34: =E27 -> 0 | F34: =F27 -> 0 | G34: =G27 -> 0 | H34: =H27 -> 5000 | I34: =I27 -> 0 | ... Y34: =Y27 -> 0 | Z34: =SUM(B34:Y34) -> 45000
A35: Flagship & Vanguard membership | B35: =B28*$B$13+B29*$B$15 -> 0 | C35: =C28*$B$13+C29*$B$15 -> 0 | D35: =D28*$B$13+D29*$B$15 -> 0 | E35: =E28*$B$13+E29*$B$15 -> 0 | F35: =F28*$B$13+F29*$B$15 -> 0 | G35: =G28*$B$13+G29*$B$15 -> 0 | H35: =H28*$B$13+H29*$B$15 -> 0 | I35: =I28*$B$13+I29*$B$15 -> 0 | ... Y35: =Y28*$B$13+Y29*$B$15 -> 1080 | Z35: =SUM(B35:Y35) -> 62220
A36: Direct costs / COGS ($)
A37: Gathering direct costs | B37: =B25*$B$9 -> 0 | C37: =C25*$B$9 -> 1600 | D37: =D25*$B$9 -> 1600 | E37: =E25*$B$9 -> 1600 | F37: =F25*$B$9 -> 1600 | G37: =G25*$B$9 -> 0 | H37: =H25*$B$9 -> 1800 | I37: =I25*$B$9 -> 1800 | ... Y37: =Y25*$B$9 -> 0 | Z37: =SUM(B37:Y37) -> 60200
A38: Corporate run direct costs | B38: =B26*$B$11 -> 0 | C38: =C26*$B$11 -> 0 | D38: =D26*$B$11 -> 0 | E38: =E26*$B$11 -> 0 | F38: =F26*$B$11 -> 0 | G38: =G26*$B$11 -> 1280 | H38: =H26*$B$11 -> 1280 | I38: =I26*$B$11 -> 1280 | ... Y38: =Y26*$B$11 -> 2560 | Z38: =SUM(B38:Y38) -> 42240
A39: Sponsorship fulfillment | B39: =B27*$B$12 -> 0 | C39: =C27*$B$12 -> 0 | D39: =D27*$B$12 -> 0 | E39: =E27*$B$12 -> 0 | F39: =F27*$B$12 -> 0 | G39: =G27*$B$12 -> 0 | H39: =H27*$B$12 -> 500 | I39: =I27*$B$12 -> 0 | ... Y39: =Y27*$B$12 -> 0 | Z39: =SUM(B39:Y39) -> 4500
A40: Flagship & Vanguard direct costs | B40: =B28*$B$14+B29*$B$16 -> 0 | C40: =C28*$B$14+C29*$B$16 -> 0 | D40: =D28*$B$14+D29*$B$16 -> 0 | E40: =E28*$B$14+E29*$B$16 -> 0 | F40: =F28*$B$14+F29*$B$16 -> 0 | G40: =G28*$B$14+G29*$B$16 -> 0 | H40: =H28*$B$14+H29*$B$16 -> 0 | I40: =I28*$B$14+I29*$B$16 -> 0 | ... Y40: =Y28*$B$14+Y29*$B$16 -> 675 | Z40: =SUM(B40:Y40) -> 44400
A42: Owner draw
A43: Owner draw, accrues monthly ($) | B43: 5000 | C43: Accrues from month 1; unpaid amounts carry forward as backpay
A44: Minimum cash kept before paying the draw ($) | B44: 10000 | C44: Draw is paid only from cash above this cushion (keeps the loan working capital untouched)

Sheet Proposed Loan Details
A1: Proposed Loan payment and interest calculator
A2: Assumption: SBA-style microloan of $15,000 over 5 years at 10% (confirm rate and term with lender).
A3: Loan Amount | C3: Term (YRS) | E3: Interest Rate | G3: Month 1 Interest | H3: Month 2 Interest | I3: Month 3 Interest | J3: Month 4 Interest | K3: Month 5 Interest | L3: Month 6 Interest | M3: Month 7 Interest | N3: Month 8 Interest | O3: Month 9 Interest | P3: Month 10 Interest | Q3: Month 11 Interest | R3: Month 12 Interest | S3: Year 1 Interest
A4: 15000 | C4: 5 | E4: 0.1 | G4: =IPMT(E4/12, 1, (C4*12), -A4) -> 125 | H4: =IPMT(E4/12, 2, (C4*12), -A4) -> 123.38579 | I4: =IPMT(E4/12, 3, (C4*12), -A4) -> 121.75812 | J4: =IPMT(E4/12, 4, (C4*12), -A4) -> 120.11689 | K4: =IPMT(E4/12, 5, (C4*12), -A4) -> 118.46198 | L4: =IPMT(E4/12, 6, (C4*12), -A4) -> 116.79329 | M4: =IPMT(E4/12, 7, (C4*12), -A4) -> 115.11068 | N4: =IPMT(E4/12, 8, (C4*12), -A4) -> 113.41406 | O4: =IPMT(E4/12, 9, (C4*12), -A4) -> 111.7033 | P4: =IPMT(E4/12, 10, (C4*12), -A4) -> 109.97828 | Q4: =IPMT(E4/12, 11, (C4*12), -A4) -> 108.23888 | R4: =IPMT(E4/12, 12, (C4*12), -A4) -> 106.48499 | S4: =SUM(G4:R4) -> 1390.4463
A6: Monthy Payment | G6: Month 13 Interest | H6: Month 14 Interest | I6: Month 15 Interest | J6: Month 16 Interest | K6: Month 17 Interest | L6: Month 18 Interest | M6: Month 19 Interest | N6: Month 20 Interest | O6: Month 21 Interest | P6: Month 22 Interest | Q6: Month 23 Interest | R6: Month 24 Interest | S6: Year 2 Interest
A7: =PMT(E4/12,C4*12, -A4) -> 318.70567 | G7: =IPMT(E4/12, 13, (C4*12), -A4) -> 104.71649 | H7: =IPMT(E4/12, 14, (C4*12), -A4) -> 102.93324 | I7: =IPMT(E4/12, 15, (C4*12), -A4) -> 101.13514 | J7: =IPMT(E4/12, 16, (C4*12), -A4) -> 99.32205 | K7: =IPMT(E4/12, 17, (C4*12), -A4) -> 97.493854 | L7: =IPMT(E4/12, 18, (C4*12), -A4) -> 95.650422 | M7: =IPMT(E4/12, 19, (C4*12), -A4) -> 93.791628 | N7: =IPMT(E4/12, 20, (C4*12), -A4) -> 91.917344 | O7: =IPMT(E4/12, 21, (C4*12), -A4) -> 90.027442 | P7: =IPMT(E4/12, 22, (C4*12), -A4) -> 88.12179 | Q7: =IPMT(E4/12, 23, (C4*12), -A4) -> 86.200257 | R7: =IPMT(E4/12, 24, (C4*12), -A4) -> 84.262712 | S7: =SUM(G7:R7) -> 1135.5724
A9: Loan Amount | C9: Term (YRS) | E9: Interest Rate | G9: Month 1 Interest | H9: Month 2 Interest | I9: Month 3 Interest | J9: Month 4 Interest | K9: Month 5 Interest | L9: Month 6 Interest | M9: Month 7 Interest | N9: Month 8 Interest | O9: Month 9 Interest | P9: Month 10 Interest | Q9: Month 11 Interest | R9: Month 12 Interest | S9: Year 1 Interest
A10: 0 | C10: 10 | E10: 0.08 | G10: =IPMT(E10/12, 1, (C10*12), -A10) -> 0 | H10: =IPMT(E10/12, 2, (C10*12), -A10) -> 0 | I10: =IPMT(E10/12, 3, (C10*12), -A10) -> 0 | J10: =IPMT(E10/12, 4, (C10*12), -A10) -> 0 | K10: =IPMT(E10/12, 5, (C10*12), -A10) -> 0 | L10: =IPMT(E10/12, 6, (C10*12), -A10) -> 0 | M10: =IPMT(E10/12, 7, (C10*12), -A10) -> 0 | N10: =IPMT(E10/12, 8, (C10*12), -A10) -> 0 | O10: =IPMT(E10/12, 9, (C10*12), -A10) -> 0 | P10: =IPMT(E10/12, 10, (C10*12), -A10) -> 0 | Q10: =IPMT(E10/12, 11, (C10*12), -A10) -> 0 | R10: =IPMT(E10/12, 12, (C10*12), -A10) -> 0 | S10: =SUM(G10:R10) -> 0
A12: Monthy Payment | G12: Month 13 Interest | H12: Month 14 Interest | I12: Month 15 Interest | J12: Month 16 Interest | K12: Month 17 Interest | L12: Month 18 Interest | M12: Month 19 Interest | N12: Month 20 Interest | O12: Month 21 Interest | P12: Month 22 Interest | Q12: Month 23 Interest | R12: Month 24 Interest | S12: Year 2 Interest
A13: =PMT(E10/12,C10*12, -A10) -> 0 | G13: =IPMT(E10/12, 13, (C10*12), -A10) -> 0 | H13: =IPMT(E10/12, 14, (C10*12), -A10) -> 0 | I13: =IPMT(E10/12, 15, (C10*12), -A10) -> 0 | J13: =IPMT(E10/12, 16, (C10*12), -A10) -> 0 | K13: =IPMT(E10/12, 17, (C10*12), -A10) -> 0 | L13: =IPMT(E10/12, 18, (C10*12), -A10) -> 0 | M13: =IPMT(E10/12, 19, (C10*12), -A10) -> 0 | N13: =IPMT(E10/12, 20, (C10*12), -A10) -> 0 | O13: =IPMT(E10/12, 21, (C10*12), -A10) -> 0 | P13: =IPMT(E10/12, 22, (C10*12), -A10) -> 0 | Q13: =IPMT(E10/12, 23, (C10*12), -A10) -> 0 | R13: =IPMT(E10/12, 24, (C10*12), -A10) -> 0 | S13: =SUM(G13:R13) -> 0
A16: Projected Business Debt Coverage Ratio
A18: Year 1 | C18: =IFERROR(('1st Year Projections'!N41+'1st Year Projections'!N33)/(('Proposed Loan Details'!A7+A13)*12),0) -> 2.1505017
A19: Year 2 | C19: =IFERROR(('2nd Year Projections'!N41 + '2nd Year Projections'!N33)/(('Proposed Loan Details'!A7+A13)*12),0) -> 15.88281

Sheet 1st Year Projections
A1: Fiscal Year Begins | B1: Business Name: Colgrid | O1: Proposed loan amount
A2: 46388 | B2: City-based real-world team game (NAICS 711320) | O2: ='Proposed Loan Details'!A4+'Proposed Loan Details'!A10 -> 15000
B3: Month 1 | C3: Month 2 | D3: Month 3 | E3: Month 4 | F3: Month 5 | G3: Month 6 | H3: Month 7 | I3: Month 8 | J3: Month 9 | K3: Month 10 | L3: Month 11 | M3: Month 12 | N3: YEARLY | P3: Percentages
A4: Revenue | B4: =A2 -> 46388 | C4: =DATE(YEAR(B4),MONTH(B4)+1,1) -> 46419 | D4: =DATE(YEAR(C4),MONTH(C4)+1,1) -> 46447 | E4: =DATE(YEAR(D4),MONTH(D4)+1,1) -> 46478 | F4: =DATE(YEAR(E4),MONTH(E4)+1,1) -> 46508 | G4: =DATE(YEAR(F4),MONTH(F4)+1,1) -> 46539 | H4: =DATE(YEAR(G4),MONTH(G4)+1,1) -> 46569 | I4: =DATE(YEAR(H4),MONTH(H4)+1,1) -> 46600 | J4: =DATE(YEAR(I4),MONTH(I4)+1,1) -> 46631 | ... N4: =DATE(YEAR(M4),MONTH(M4)+1,1) -> 46753 | O4: Assumptions. Please describe how figures were derived.
A5: Gathering tickets & Season Passes | B5: =Assumptions!B32 -> 0 | C5: =Assumptions!C32 -> 2920 | D5: =Assumptions!D32 -> 2920 | E5: =Assumptions!E32 -> 2920 | F5: =Assumptions!F32 -> 2920 | G5: =Assumptions!G32 -> 0 | H5: =Assumptions!H32 -> 3285 | I5: =Assumptions!I32 -> 3285 | ... M5: =Assumptions!M32 -> 2190 | N5: =SUM(B5:M5) -> 36865 | O5: Players x $73 blended ticket (60% single $75, 40% pass $70). See Assumptions tab.
A6: Corporate private runs | B6: =Assumptions!B33 -> 0 | C6: =Assumptions!C33 -> 0 | D6: =Assumptions!D33 -> 0 | E6: =Assumptions!E33 -> 0 | F6: =Assumptions!F33 -> 0 | G6: =Assumptions!G33 -> 2500 | H6: =Assumptions!H33 -> 2500 | I6: =Assumptions!I33 -> 2500 | ... M6: =Assumptions!M33 -> 5000 | N6: =SUM(B6:M6) -> 22500 | O6: Private runs x $2,500
A7: Sponsorships | B7: =Assumptions!B34 -> 0 | C7: =Assumptions!C34 -> 0 | D7: =Assumptions!D34 -> 0 | E7: =Assumptions!E34 -> 0 | F7: =Assumptions!F34 -> 0 | G7: =Assumptions!G34 -> 0 | H7: =Assumptions!H34 -> 5000 | I7: =Assumptions!I34 -> 0 | ... M7: =Assumptions!M34 -> 0 | N7: =SUM(B7:M7) -> 10000 | O7: BID / tourism / brand sponsors per season
A8: Flagship & Vanguard membership | B8: =Assumptions!B35 -> 0 | C8: =Assumptions!C35 -> 0 | D8: =Assumptions!D35 -> 0 | E8: =Assumptions!E35 -> 0 | F8: =Assumptions!F35 -> 0 | G8: =Assumptions!G35 -> 0 | H8: =Assumptions!H35 -> 0 | I8: =Assumptions!I35 -> 0 | ... M8: =Assumptions!M35 -> 0 | N8: =SUM(B8:M8) -> 0 | O8: Starts in year 2
A9: Total Revenue (Sales) | B9: =SUM(B5:B8) -> 0 | C9: =SUM(C5:C8) -> 2920 | D9: =SUM(D5:D8) -> 2920 | E9: =SUM(E5:E8) -> 2920 | F9: =SUM(F5:F8) -> 2920 | G9: =SUM(G5:G8) -> 2500 | H9: =SUM(H5:H8) -> 10785 | I9: =SUM(I5:I8) -> 5785 | ... M9: =SUM(M5:M8) -> 7190 | N9: =SUM(B9:M9) -> 69365
A11: Cost of Goods Sold
A12: Gathering tickets & Season Passes (direct costs) | B12: =Assumptions!B37 -> 0 | C12: =Assumptions!C37 -> 1600 | D12: =Assumptions!D37 -> 1600 | E12: =Assumptions!E37 -> 1600 | F12: =Assumptions!F37 -> 1600 | G12: =Assumptions!G37 -> 0 | H12: =Assumptions!H37 -> 1800 | I12: =Assumptions!I37 -> 1800 | ... M12: =Assumptions!M37 -> 1200 | N12: =SUM(B12:M12) -> 20200 | O12: $40 per player: hosts $18, finale meal $12, game master $6, keepsakes $4 | P12: =IFERROR(N12/N5,"") -> 0.54794521
A13: Corporate private runs (direct costs) | B13: =Assumptions!B38 -> 0 | C13: =Assumptions!C38 -> 0 | D13: =Assumptions!D38 -> 0 | E13: =Assumptions!E38 -> 0 | F13: =Assumptions!F38 -> 0 | G13: =Assumptions!G38 -> 1280 | H13: =Assumptions!H38 -> 1280 | I13: =Assumptions!I38 -> 1280 | ... M13: =Assumptions!M38 -> 2560 | N13: =SUM(B13:M13) -> 11520 | O13: $1,280 per run | P13: =IFERROR(N13/N6,"") -> 0.512
A14: Sponsorships (direct costs) | B14: =Assumptions!B39 -> 0 | C14: =Assumptions!C39 -> 0 | D14: =Assumptions!D39 -> 0 | E14: =Assumptions!E39 -> 0 | F14: =Assumptions!F39 -> 0 | G14: =Assumptions!G39 -> 0 | H14: =Assumptions!H39 -> 500 | I14: =Assumptions!I39 -> 0 | ... M14: =Assumptions!M39 -> 0 | N14: =SUM(B14:M14) -> 1000 | O14: 10% of sponsor revenue | P14: =IFERROR(N14/N7,"") -> 0.1
A15: Flagship & Vanguard membership (direct costs) | B15: =Assumptions!B40 -> 0 | C15: =Assumptions!C40 -> 0 | D15: =Assumptions!D40 -> 0 | E15: =Assumptions!E40 -> 0 | F15: =Assumptions!F40 -> 0 | G15: =Assumptions!G40 -> 0 | H15: =Assumptions!H40 -> 0 | I15: =Assumptions!I40 -> 0 | ... M15: =Assumptions!M40 -> 0 | N15: =SUM(B15:M15) -> 0 | O15: Flagship $545/player; Vanguard $225/member | P15: =IFERROR(N15/N8,"")
A16: Total Cost of Goods Sold | B16: =SUM(B12:B15) -> 0 | C16: =SUM(C12:C15) -> 1600 | D16: =SUM(D12:D15) -> 1600 | E16: =SUM(E12:E15) -> 1600 | F16: =SUM(F12:F15) -> 1600 | G16: =SUM(G12:G15) -> 1280 | H16: =SUM(H12:H15) -> 3580 | I16: =SUM(I12:I15) -> 3080 | ... M16: =SUM(M12:M15) -> 3760 | N16: =SUM(B16:M16) -> 32720 | P16: =IFERROR(N16/N9,"") -> 0.47170763
A18: Gross Profit | B18: =B9-B16 -> 0 | C18: =C9-C16 -> 1320 | D18: =D9-D16 -> 1320 | E18: =E9-E16 -> 1320 | F18: =F9-F16 -> 1320 | G18: =G9-G16 -> 1220 | H18: =H9-H16 -> 7205 | I18: =I9-I16 -> 2705 | ... N18: =N9-N16 -> 36645 | P18: =N18/N9 -> 0.52829237
A20: Expenses
A21: Marketing | B21: 600 | C21: 800 | D21: 800 | E21: 800 | F21: 800 | G21: 400 | H21: 800 | I21: 800 | J21: 1000 | K21: 800 | L21: 800 | M21: 600 | N21: =SUM(B21:M21) -> 9000 | O21: Social ads, player photos/video, launch posts; ~$18 per ticketed player
A22: Bank Charges | B22: 20 | C22: 20 | D22: 20 | E22: 20 | F22: 20 | G22: 20 | H22: 20 | I22: 20 | J22: 20 | K22: 20 | L22: 20 | M22: 20 | N22: =SUM(B22:M22) -> 240 | O22: Business checking
A23: Car-Truck | B23: 100 | C23: 100 | D23: 100 | E23: 100 | F23: 100 | G23: 100 | H23: 100 | I23: 100 | J23: 150 | K23: 150 | L23: 150 | M23: 150 | N23: =SUM(B23:M23) -> 1400 | O23: Mileage: host scouting; Ogden trips from Sep
A24: Utilities | B24: 0 | C24: 0 | D24: 0 | E24: 0 | F24: 0 | G24: 0 | H24: 0 | I24: 0 | J24: 0 | K24: 0 | L24: 0 | M24: 0 | N24: =SUM(B24:M24) -> 0 | O24: Home-based; no facility (events use host venues)
A25: Rent/Lease | B25: 75 | C25: 75 | D25: 75 | E25: 75 | F25: 75 | G25: 75 | H25: 75 | I25: 75 | J25: 75 | K25: 75 | L25: 75 | M25: 75 | N25: =SUM(B25:M25) -> 900 | O25: Small storage unit for keepsakes, field guides, props
A26: Merchant Service Fees | B26: =B9*Assumptions!$B$17 -> 0 | C26: =C9*Assumptions!$B$17 -> 43.8 | D26: =D9*Assumptions!$B$17 -> 43.8 | E26: =E9*Assumptions!$B$17 -> 43.8 | F26: =F9*Assumptions!$B$17 -> 43.8 | G26: =G9*Assumptions!$B$17 -> 37.5 | H26: =H9*Assumptions!$B$17 -> 161.775 | I26: =I9*Assumptions!$B$17 -> 86.775 | ... M26: =M9*Assumptions!$B$17 -> 107.85 | N26: =SUM(B26:M26) -> 1040.475 | O26: 1.5% of revenue (ticket fees passed to buyer)
A27: Office & Supplies | B27: 100 | C27: 100 | D27: 100 | E27: 100 | F27: 100 | G27: 100 | H27: 100 | I27: 100 | J27: 100 | K27: 100 | L27: 100 | M27: 100 | N27: =SUM(B27:M27) -> 1200 | O27: Printing, quest props not tied to a single session
A28: Office Meals / Entertainment | B28: 75 | C28: 75 | D28: 75 | E28: 75 | F28: 75 | G28: 75 | H28: 75 | I28: 75 | J28: 75 | K28: 75 | L28: 75 | M28: 75 | N28: =SUM(B28:M28) -> 900 | O28: Host and venue scouting meetings
A29: Repairs | B29: 0 | C29: 0 | D29: 0 | E29: 0 | F29: 0 | G29: 0 | H29: 0 | I29: 0 | J29: 0 | K29: 0 | L29: 0 | M29: 0 | N29: =SUM(B29:M29) -> 0
A30: Salary Expenses | B30: =Payroll!I13 -> 0 | C30: =Payroll!J13 -> 0 | D30: =Payroll!K13 -> 0 | E30: =Payroll!L13 -> 0 | F30: =Payroll!M13 -> 0 | G30: =Payroll!N13 -> 0 | H30: =Payroll!O13 -> 0 | I30: =Payroll!P13 -> 0 | ... M30: =Payroll!T13 -> 800 | N30: =SUM(B30:M30) -> 3200 | O30: See Payroll tab: part-time Ogden chapter lead from Sep. Owner draw is on the Cash Flow tab
A31: Telephone & Internet | B31: 75 | C31: 75 | D31: 75 | E31: 75 | F31: 75 | G31: 75 | H31: 75 | I31: 75 | J31: 75 | K31: 75 | L31: 75 | M31: 75 | N31: =SUM(B31:M31) -> 900 | O31: Phone + group texting for pre-game messages
A32: Insurance | B32: 100 | C32: 100 | D32: 100 | E32: 100 | F32: 100 | G32: 100 | H32: 100 | I32: 100 | J32: 100 | K32: 100 | L32: 100 | M32: 100 | N32: =SUM(B32:M32) -> 1200 | O32: General liability + event coverage (~$1,200/yr); get quotes
A33: Interest Expense Loan #1 | B33: ='Proposed Loan Details'!G4 -> 125 | C33: ='Proposed Loan Details'!H4 -> 123.38579 | D33: ='Proposed Loan Details'!I4 -> 121.75812 | E33: ='Proposed Loan Details'!J4 -> 120.11689 | F33: ='Proposed Loan Details'!K4 -> 118.46198 | G33: ='Proposed Loan Details'!L4 -> 116.79329 | H33: ='Proposed Loan Details'!M4 -> 115.11068 | I33: ='Proposed Loan Details'!N4 -> 113.41406 | ... M33: ='Proposed Loan Details'!R4 -> 106.48499 | N33: =SUM(B33:M33) -> 1390.4463 | O33: $15,000 loan, 5 yrs, 10% (Proposed Loan Details)
A34: Interest Expense Loan #2 | B34: ='Proposed Loan Details'!G10 -> 0 | C34: ='Proposed Loan Details'!H10 -> 0 | D34: ='Proposed Loan Details'!I10 -> 0 | E34: ='Proposed Loan Details'!J10 -> 0 | F34: ='Proposed Loan Details'!K10 -> 0 | G34: ='Proposed Loan Details'!L10 -> 0 | H34: ='Proposed Loan Details'!M10 -> 0 | I34: ='Proposed Loan Details'!N10 -> 0 | ... M34: ='Proposed Loan Details'!R10 -> 0 | N34: =SUM(B34:M34) -> 0 | O34: No second loan
A35: Software & Web Pass | B35: 120 | C35: 120 | D35: 120 | E35: 120 | F35: 120 | G35: 120 | H35: 120 | I35: 120 | J35: 120 | K35: 120 | L35: 120 | M35: 120 | N35: =SUM(B35:M35) -> 1440 | O35: Web pass hosting, ticketing plan, email, domain
A36: Professional Fees (legal, trademark, CPA) | B36: 1500 | C36: 0 | D36: 1000 | E36: 100 | F36: 100 | G36: 100 | H36: 100 | I36: 100 | J36: 100 | K36: 100 | L36: 100 | M36: 100 | N36: =SUM(B36:M36) -> 3400 | O36: LLC/legal review; trademark filing after naming; bookkeeping
A37: Licenses, Permits & Fees | B37: 50 | C37: 50 | D37: 50 | E37: 50 | F37: 50 | G37: 50 | H37: 50 | I37: 50 | J37: 50 | K37: 50 | L37: 50 | M37: 50 | N37: =SUM(B37:M37) -> 600 | O37: Business license, event permits where needed
A38: Brand & Design | B38: 1500 | C38: 1500 | D38: 0 | E38: 0 | F38: 0 | G38: 0 | H38: 0 | I38: 0 | J38: 0 | K38: 0 | L38: 0 | M38: 0 | N38: =SUM(B38:M38) -> 3000 | O38: Identity design after naming (logo, badge art, field guide)
A39: Total Expenses | B39: =SUM(B21:B38) -> 4440 | C39: =SUM(C21:C38) -> 3182.1858 | D39: =SUM(D21:D38) -> 2680.5581 | E39: =SUM(E21:E38) -> 1778.9169 | F39: =SUM(F21:F38) -> 1777.262 | G39: =SUM(G21:G38) -> 1369.2933 | H39: =SUM(H21:H38) -> 1891.8857 | I39: =SUM(I21:I38) -> 1815.1891 | ... N39: =SUM(N21:N38) -> 29810.921 | P39: =N39/N9 -> 0.42976892
Q40: NAICS 711320
A41: Net Profit Before Taxes | B41: =B18-B39 -> -4440 | C41: =C18-C39 -> -1862.1858 | D41: =D18-D39 -> -1360.5581 | E41: =E18-E39 -> -458.91689 | F41: =F18-F39 -> -457.26198 | G41: =G18-G39 -> -149.29329 | H41: =H18-H39 -> 5313.1143 | I41: =I18-I39 -> 889.81094 | ... N41: =N18-N39 -> 6834.0787 | P41: =N41/N9 -> 0.098523445 | Q41: Promoters of events without facilities

Sheet Payroll
A1: Fiscal Year Begins
A2: ='1st Year Projections'!A2 -> 46388 | B2: Payroll
I4: Month 1 | J4: Month 2 | K4: Month 3 | L4: Month 4 | M4: Month 5 | N4: Month 6 | O4: Month 7 | P4: Month 8 | Q4: Month 9 | R4: Month 10 | S4: Month 11 | T4: Month 12 | U4: YEARLY
C5: Annual | D5: Monthly | E5: Hourly* | H5: Payroll | I5: =A2 -> 46388 | J5: =DATE(YEAR(I5),MONTH(I5)+1,1) -> 46419 | K5: =DATE(YEAR(J5),MONTH(J5)+1,1) -> 46447 | L5: =DATE(YEAR(K5),MONTH(K5)+1,1) -> 46478 | M5: =DATE(YEAR(L5),MONTH(L5)+1,1) -> 46508 | N5: =DATE(YEAR(M5),MONTH(M5)+1,1) -> 46539 | O5: =DATE(YEAR(N5),MONTH(N5)+1,1) -> 46569 | P5: =DATE(YEAR(O5),MONTH(O5)+1,1) -> 46600 | Q5: =DATE(YEAR(P5),MONTH(P5)+1,1) -> 46631 | ... U5: =DATE(YEAR(T5),MONTH(T5)+1,1) -> 46753
B6: Owner Salary (none; owner takes a $5,000/mo draw, see Cash Flow) | C6: 0 | D6: =C6/12 -> 0 | E6: =C6/2080 -> 0 | H6: =B6 -> Owner Salary (none; owner takes a $5,000/mo draw, see Cash Flow) | I6: =D6 -> 0 | J6: =D6 -> 0 | K6: =D6 -> 0 | L6: =D6 -> 0 | M6: =D6 -> 0 | N6: =D6 -> 0 | O6: =D6 -> 0 | P6: =D6 -> 0 | Q6: =D6 -> 0 | R6: =D6 -> 0 | S6: =D6 -> 0 | T6: =D6 -> 0 | U6: =SUM(I6:T6) -> 0
B7: Chapter Lead - Ogden (part-time) | C7: 9600 | D7: =C7/12 -> 800 | E7: =C7/480 -> 20 | H7: =B7 -> Chapter Lead - Ogden (part-time) | I7: 0 | J7: 0 | K7: 0 | L7: 0 | M7: 0 | N7: 0 | O7: 0 | P7: 0 | Q7: =D7 -> 800 | R7: =D7 -> 800 | S7: =D7 -> 800 | T7: =D7 -> 800 | U7: =SUM(I7:T7) -> 3200
B8: Chapter Lead - Provo (part-time, year 2) | C8: 0 | D8: =C8/12 -> 0 | E8: =C8/2080 -> 0 | H8: =B8 -> Chapter Lead - Provo (part-time, year 2) | I8: =D8 -> 0 | J8: =D8 -> 0 | K8: =D8 -> 0 | L8: =D8 -> 0 | M8: =D8 -> 0 | N8: =D8 -> 0 | O8: =D8 -> 0 | P8: =D8 -> 0 | Q8: =D8 -> 0 | R8: =D8 -> 0 | S8: =D8 -> 0 | T8: =D8 -> 0 | U8: =SUM(I8:T8) -> 0
B9: Admin Assistant | C9: 0 | D9: =C9/12 -> 0 | E9: =C9/2080 -> 0 | H9: =B9 -> Admin Assistant | I9: =D9 -> 0 | J9: =D9 -> 0 | K9: =D9 -> 0 | L9: =D9 -> 0 | M9: =D9 -> 0 | N9: =D9 -> 0 | O9: =D9 -> 0 | P9: =D9 -> 0 | Q9: =D9 -> 0 | R9: =D9 -> 0 | S9: =D9 -> 0 | T9: =D9 -> 0 | U9: =SUM(I9:T9) -> 0
B10: Event crew (covered in direct costs) | C10: 0 | D10: =C10/12 -> 0 | E10: =C10/1040 -> 0 | H10: =B10 -> Event crew (covered in direct costs) | I10: =D10 -> 0 | J10: =D10 -> 0 | K10: =D10 -> 0 | L10: =D10 -> 0 | M10: =D10 -> 0 | N10: =D10 -> 0 | O10: =D10 -> 0 | P10: =D10 -> 0 | Q10: =D10 -> 0 | R10: =D10 -> 0 | S10: =D10 -> 0 | T10: =D10 -> 0 | U10: =SUM(I10:T10) -> 0
B11: Event crew (covered in direct costs) | C11: 0 | D11: =C11/12 -> 0 | E11: =C11/1040 -> 0 | H11: =B11 -> Event crew (covered in direct costs) | I11: =D11 -> 0 | J11: =D11 -> 0 | K11: =D11 -> 0 | L11: =D11 -> 0 | M11: 0 | N11: 0 | O11: 0 | P11: 0 | Q11: 0 | R11: 0 | S11: 0 | T11: =D11 -> 0 | U11: =SUM(I11:T11) -> 0
B13: Max Total Monthly | D13: =SUM(D6:D11) -> 800 | H13: Total Monthly | I13: =SUM(I6:I12) -> 0 | J13: =SUM(J6:J12) -> 0 | K13: =SUM(K6:K12) -> 0 | L13: =SUM(L6:L12) -> 0 | M13: =SUM(M6:M12) -> 0 | N13: =SUM(N6:N12) -> 0 | O13: =SUM(O6:O12) -> 0 | P13: =SUM(P6:P12) -> 0 | ... U13: =SUM(U6:U12) -> 3200
H15: Assumptions | I15: =I5 -> 46388 | J15: =DATE(YEAR(I15),MONTH(I15)+1,1) -> 46419 | K15: =DATE(YEAR(J15),MONTH(J15)+1,1) -> 46447 | L15: =DATE(YEAR(K15),MONTH(K15)+1,1) -> 46478 | M15: =DATE(YEAR(L15),MONTH(L15)+1,1) -> 46508 | N15: =DATE(YEAR(M15),MONTH(M15)+1,1) -> 46539 | O15: =DATE(YEAR(N15),MONTH(N15)+1,1) -> 46569 | P15: =DATE(YEAR(O15),MONTH(O15)+1,1) -> 46600 | Q15: =DATE(YEAR(P15),MONTH(P15)+1,1) -> 46631 | ... T15: =DATE(YEAR(S15),MONTH(S15)+1,1) -> 46722
I16: Month 1: | J16: Month 2: | K16: Month 3: | L16: Month 4: | M16: Month 5: | N16: Month 6: | O16: Month 7: | P16: Month 8: | Q16: Month 9: | R16: Month 10: | S16: Month 11: | T16: Month 12:
B17: =B6 -> Owner Salary (none; owner takes a $5,000/mo draw, see Cash Flow)
B18: Owner runs strategy, hosts, partnerships and game design. Paid by an owner draw of $5,000/month that accrues from month 1 and is paid out when cash allows (deferred backpay); see Cash Flow tabs.
B20: =B7 -> Chapter Lead - Ogden (part-time)
B21: Part-time lead trained on the chapter playbook: recruits hosts, runs game nights in Ogden. ~40 hrs/month at $20/hr from Sep of year 1.
B23: =B8 -> Chapter Lead - Provo (part-time, year 2)
B24: Same role for Provo, starting Jul of year 2.
B26: =B9 -> Admin Assistant
B27: Not needed in years 1-2.
B29: =B10 -> Event crew (covered in direct costs)
B30: Game master on the night is paid per session and counted in the $40 direct cost per player.
B32: =B11 -> Event crew (covered in direct costs)
B33: Same as above.
A37: *The Hourly rate above is assumed the employees are working 40 hours a weeks which is 2080 hours a year. If a employee is seasonal or part time, the hourly rate can be manually input or the formula can be updated.

Sheet Cash Flow 1st Year
A1: 12 Month Cash Flow Statement
A2: Cash Flow (12 months) | G2: ='1st Year Projections'!B1 -> Business Name: Colgrid | N2: Fiscal Year Begins: | O2: ='1st Year Projections'!A2 -> 46388
B3: Pre-Startup EST | C3: =O2 -> 46388 | D3: =DATE(YEAR(C3),MONTH(C3)+1,1) -> 46419 | E3: =DATE(YEAR(D3),MONTH(D3)+1,1) -> 46447 | F3: =DATE(YEAR(E3),MONTH(E3)+1,1) -> 46478 | G3: =DATE(YEAR(F3),MONTH(F3)+1,1) -> 46508 | H3: =DATE(YEAR(G3),MONTH(G3)+1,1) -> 46539 | I3: =DATE(YEAR(H3),MONTH(H3)+1,1) -> 46569 | J3: =DATE(YEAR(I3),MONTH(I3)+1,1) -> 46600 | K3: =DATE(YEAR(J3),MONTH(J3)+1,1) -> 46631 | ... N3: =DATE(YEAR(M3),MONTH(M3)+1,1) -> 46722
A4: Cash on Hand (beginning of month) - owner equity in Pre-Startup | B4: 3000 | C4: =B38 -> 13000 | D4: =C38 -> 8366.2943 | E4: =D38 -> 6308.7887 | F4: =E38 -> 4751.283 | G4: =F38 -> 4093.7773 | H4: =G38 -> 3436.2716 | I4: =H38 -> 3085.066 | J4: =I38 -> 8194.5853 | ... N4: =M38 -> 10000
A6: CASH RECEIPTS
A7: Cash Sales | C7: ='1st Year Projections'!B9 -> 0 | D7: ='1st Year Projections'!C9 -> 2920 | E7: ='1st Year Projections'!D9 -> 2920 | F7: ='1st Year Projections'!E9 -> 2920 | G7: ='1st Year Projections'!F9 -> 2920 | H7: ='1st Year Projections'!G9 -> 2500 | I7: ='1st Year Projections'!H9 -> 10785 | J7: ='1st Year Projections'!I9 -> 5785 | ... N7: ='1st Year Projections'!M9 -> 7190
A8: Collections fm CR accounts
A9: Loan proceeds / working capital injection | B9: ='Proposed Loan Details'!A4 -> 15000
A10: TOTAL CASH RECEIPTS | B10: =SUM(B7:B9) -> 15000 | C10: =SUM(C7:C9) -> 0 | D10: =SUM(D7:D9) -> 2920 | E10: =SUM(E7:E9) -> 2920 | F10: =SUM(F7:F9) -> 2920 | G10: =SUM(G7:G9) -> 2920 | H10: =SUM(H7:H9) -> 2500 | I10: =SUM(I7:I9) -> 10785 | ... N10: =SUM(N7:N9) -> 7190
A11: Total Cash Available (before cash out) | B11: =(B4+B10) -> 18000 | C11: =(C4+C10) -> 13000 | D11: =(D4+D10) -> 11286.294 | E11: =(E4+E10) -> 9228.7887 | F11: =(F4+F10) -> 7671.283 | G11: =(G4+G10) -> 7013.7773 | H11: =(H4+H10) -> 5936.2716 | I11: =(I4+I10) -> 13870.066 | ... N11: =(N4+N10) -> 17190
A13: CASH PAID OUT
A14: ='1st Year Projections'!A21 -> Marketing | C14: ='1st Year Projections'!B21 -> 600 | D14: ='1st Year Projections'!C21 -> 800 | E14: ='1st Year Projections'!D21 -> 800 | F14: ='1st Year Projections'!E21 -> 800 | G14: ='1st Year Projections'!F21 -> 800 | H14: ='1st Year Projections'!G21 -> 400 | I14: ='1st Year Projections'!H21 -> 800 | J14: ='1st Year Projections'!I21 -> 800 | ... N14: ='1st Year Projections'!M21 -> 600
A15: ='1st Year Projections'!A22 -> Bank Charges | C15: ='1st Year Projections'!B22 -> 20 | D15: ='1st Year Projections'!C22 -> 20 | E15: ='1st Year Projections'!D22 -> 20 | F15: ='1st Year Projections'!E22 -> 20 | G15: ='1st Year Projections'!F22 -> 20 | H15: ='1st Year Projections'!G22 -> 20 | I15: ='1st Year Projections'!H22 -> 20 | J15: ='1st Year Projections'!I22 -> 20 | ... N15: ='1st Year Projections'!M22 -> 20
A16: ='1st Year Projections'!A23 -> Car-Truck | C16: ='1st Year Projections'!B23 -> 100 | D16: ='1st Year Projections'!C23 -> 100 | E16: ='1st Year Projections'!D23 -> 100 | F16: ='1st Year Projections'!E23 -> 100 | G16: ='1st Year Projections'!F23 -> 100 | H16: ='1st Year Projections'!G23 -> 100 | I16: ='1st Year Projections'!H23 -> 100 | J16: ='1st Year Projections'!I23 -> 100 | ... N16: ='1st Year Projections'!M23 -> 150
A17: ='1st Year Projections'!A24 -> Utilities | C17: ='1st Year Projections'!B24 -> 0 | D17: ='1st Year Projections'!C24 -> 0 | E17: ='1st Year Projections'!D24 -> 0 | F17: ='1st Year Projections'!E24 -> 0 | G17: ='1st Year Projections'!F24 -> 0 | H17: ='1st Year Projections'!G24 -> 0 | I17: ='1st Year Projections'!H24 -> 0 | J17: ='1st Year Projections'!I24 -> 0 | ... N17: ='1st Year Projections'!M24 -> 0
A18: ='1st Year Projections'!A25 -> Rent/Lease | C18: ='1st Year Projections'!B25 -> 75 | D18: ='1st Year Projections'!C25 -> 75 | E18: ='1st Year Projections'!D25 -> 75 | F18: ='1st Year Projections'!E25 -> 75 | G18: ='1st Year Projections'!F25 -> 75 | H18: ='1st Year Projections'!G25 -> 75 | I18: ='1st Year Projections'!H25 -> 75 | J18: ='1st Year Projections'!I25 -> 75 | ... N18: ='1st Year Projections'!M25 -> 75
A19: ='1st Year Projections'!A26 -> Merchant Service Fees | C19: ='1st Year Projections'!B26 -> 0 | D19: ='1st Year Projections'!C26 -> 43.8 | E19: ='1st Year Projections'!D26 -> 43.8 | F19: ='1st Year Projections'!E26 -> 43.8 | G19: ='1st Year Projections'!F26 -> 43.8 | H19: ='1st Year Projections'!G26 -> 37.5 | I19: ='1st Year Projections'!H26 -> 161.775 | J19: ='1st Year Projections'!I26 -> 86.775 | ... N19: ='1st Year Projections'!M26 -> 107.85
A20: ='1st Year Projections'!A27 -> Office & Supplies | C20: ='1st Year Projections'!B27 -> 100 | D20: ='1st Year Projections'!C27 -> 100 | E20: ='1st Year Projections'!D27 -> 100 | F20: ='1st Year Projections'!E27 -> 100 | G20: ='1st Year Projections'!F27 -> 100 | H20: ='1st Year Projections'!G27 -> 100 | I20: ='1st Year Projections'!H27 -> 100 | J20: ='1st Year Projections'!I27 -> 100 | ... N20: ='1st Year Projections'!M27 -> 100
A21: ='1st Year Projections'!A28 -> Office Meals / Entertainment | C21: ='1st Year Projections'!B28 -> 75 | D21: ='1st Year Projections'!C28 -> 75 | E21: ='1st Year Projections'!D28 -> 75 | F21: ='1st Year Projections'!E28 -> 75 | G21: ='1st Year Projections'!F28 -> 75 | H21: ='1st Year Projections'!G28 -> 75 | I21: ='1st Year Projections'!H28 -> 75 | J21: ='1st Year Projections'!I28 -> 75 | ... N21: ='1st Year Projections'!M28 -> 75
A22: ='1st Year Projections'!A29 -> Repairs | C22: ='1st Year Projections'!B29 -> 0 | D22: ='1st Year Projections'!C29 -> 0 | E22: ='1st Year Projections'!D29 -> 0 | F22: ='1st Year Projections'!E29 -> 0 | G22: ='1st Year Projections'!F29 -> 0 | H22: ='1st Year Projections'!G29 -> 0 | I22: ='1st Year Projections'!H29 -> 0 | J22: ='1st Year Projections'!I29 -> 0 | ... N22: ='1st Year Projections'!M29 -> 0
A23: ='1st Year Projections'!A30 -> Salary Expenses | C23: ='1st Year Projections'!B30 -> 0 | D23: ='1st Year Projections'!C30 -> 0 | E23: ='1st Year Projections'!D30 -> 0 | F23: ='1st Year Projections'!E30 -> 0 | G23: ='1st Year Projections'!F30 -> 0 | H23: ='1st Year Projections'!G30 -> 0 | I23: ='1st Year Projections'!H30 -> 0 | J23: ='1st Year Projections'!I30 -> 0 | ... N23: ='1st Year Projections'!M30 -> 800
A24: ='1st Year Projections'!A31 -> Telephone & Internet | C24: ='1st Year Projections'!B31 -> 75 | D24: ='1st Year Projections'!C31 -> 75 | E24: ='1st Year Projections'!D31 -> 75 | F24: ='1st Year Projections'!E31 -> 75 | G24: ='1st Year Projections'!F31 -> 75 | H24: ='1st Year Projections'!G31 -> 75 | I24: ='1st Year Projections'!H31 -> 75 | J24: ='1st Year Projections'!I31 -> 75 | ... N24: ='1st Year Projections'!M31 -> 75
A25: ='1st Year Projections'!A32 -> Insurance | C25: ='1st Year Projections'!B32 -> 100 | D25: ='1st Year Projections'!C32 -> 100 | E25: ='1st Year Projections'!D32 -> 100 | F25: ='1st Year Projections'!E32 -> 100 | G25: ='1st Year Projections'!F32 -> 100 | H25: ='1st Year Projections'!G32 -> 100 | I25: ='1st Year Projections'!H32 -> 100 | J25: ='1st Year Projections'!I32 -> 100 | ... N25: ='1st Year Projections'!M32 -> 100
... A31: ='1st Year Projections'!A38 -> Brand & Design | C31: ='1st Year Projections'!B38 -> 1500 | D31: ='1st Year Projections'!C38 -> 1500 | E31: ='1st Year Projections'!D38 -> 0 | F31: ='1st Year Projections'!E38 -> 0 | G31: ='1st Year Projections'!F38 -> 0 | H31: ='1st Year Projections'!G38 -> 0 | I31: ='1st Year Projections'!H38 -> 0 | J31: ='1st Year Projections'!I38 -> 0 | ... N31: ='1st Year Projections'!M38 -> 0
A32: Loan principal payment | C32: ='Proposed Loan Details'!$A$7-'1st Year Projections'!B33 -> 193.70567 | D32: ='Proposed Loan Details'!$A$7-'1st Year Projections'!C33 -> 195.31988 | E32: ='Proposed Loan Details'!$A$7-'1st Year Projections'!D33 -> 196.94755 | F32: ='Proposed Loan Details'!$A$7-'1st Year Projections'!E33 -> 198.58878 | G32: ='Proposed Loan Details'!$A$7-'1st Year Projections'!F33 -> 200.24369 | H32: ='Proposed Loan Details'!$A$7-'1st Year Projections'!G33 -> 201.91238 | I32: ='Proposed Loan Details'!$A$7-'1st Year Projections'!H33 -> 203.59499 | J32: ='Proposed Loan Details'!$A$7-'1st Year Projections'!I33 -> 205.29161 | ... N32: ='Proposed Loan Details'!$A$7-'1st Year Projections'!M33 -> 212.22068
A33: SUBTOTAL | B33: =SUM(B14:B32) -> 0 | C33: =SUM(C14:C32) -> 4633.7057 | D33: =SUM(D14:D32) -> 3377.5057 | E33: =SUM(E14:E32) -> 2877.5057 | F33: =SUM(F14:F32) -> 1977.5057 | G33: =SUM(G14:G32) -> 1977.5057 | H33: =SUM(H14:H32) -> 1571.2057 | I33: =SUM(I14:I32) -> 2095.4807 | ... N33: =SUM(N14:N32) -> 2691.5557
A34: Capital purchase (COGs) | C34: ='1st Year Projections'!B16 -> 0 | D34: ='1st Year Projections'!C16 -> 1600 | E34: ='1st Year Projections'!D16 -> 1600 | F34: ='1st Year Projections'!E16 -> 1600 | G34: ='1st Year Projections'!F16 -> 1600 | H34: ='1st Year Projections'!G16 -> 1280 | I34: ='1st Year Projections'!H16 -> 3580 | J34: ='1st Year Projections'!I16 -> 3080 | ... N34: ='1st Year Projections'!M16 -> 3760
A35: Other startup costs | B35: 5000
A36: Owners' Withdrawal (draw paid) | C36: =MIN(0+Assumptions!$B$43,MAX(0,C11-C33-C34-C35-Assumptions!$B$44)) -> 0 | D36: =MIN(C48+Assumptions!$B$43,MAX(0,D11-D33-D34-D35-Assumptions!$B$44)) -> 0 | E36: =MIN(D48+Assumptions!$B$43,MAX(0,E11-E33-E34-E35-Assumptions!$B$44)) -> 0 | F36: =MIN(E48+Assumptions!$B$43,MAX(0,F11-F33-F34-F35-Assumptions!$B$44)) -> 0 | G36: =MIN(F48+Assumptions!$B$43,MAX(0,G11-G33-G34-G35-Assumptions!$B$44)) -> 0 | H36: =MIN(G48+Assumptions!$B$43,MAX(0,H11-H33-H34-H35-Assumptions!$B$44)) -> 0 | I36: =MIN(H48+Assumptions!$B$43,MAX(0,I11-I33-I34-I35-Assumptions!$B$44)) -> 0 | J36: =MIN(I48+Assumptions!$B$43,MAX(0,J11-J33-J34-J35-Assumptions!$B$44)) -> 0 | K36: =MIN(J48+Assumptions!$B$43,MAX(0,K11-K33-K34-K35-Assumptions!$B$44)) -> 3895.774 | ... N36: =MIN(M48+Assumptions!$B$43,MAX(0,N11-N33-N34-N35-Assumptions!$B$44)) -> 738.44433
A37: TOTAL CASH PAID OUT | B37: =SUM(B33:B36) -> 5000 | C37: =SUM(C33:C36) -> 4633.7057 | D37: =SUM(D33:D36) -> 4977.5057 | E37: =SUM(E33:E36) -> 4477.5057 | F37: =SUM(F33:F36) -> 3577.5057 | G37: =SUM(G33:G36) -> 3577.5057 | H37: =SUM(H33:H36) -> 2851.2057 | I37: =SUM(I33:I36) -> 5675.4807 | ... N37: =SUM(N33:N36) -> 7190
A38: Cash Position (end of month) | B38: =(B11-B37) -> 13000 | C38: =(C11-C37) -> 8366.2943 | D38: =(D11-D37) -> 6308.7887 | E38: =(E11-E37) -> 4751.283 | F38: =(F11-F37) -> 4093.7773 | G38: =(G11-G37) -> 3436.2716 | H38: =(H11-H37) -> 3085.066 | I38: =(I11-I37) -> 8194.5853 | ... N38: =(N11-N37) -> 10000
A39: Pre-startup costs: web pass build $3,000; keepsake tooling + first badge run $1,200; field guides & quest kits $500; website & domains $300.
A40: ESSENTIAL OPERATING DATA (non cash flow information)
A41: Sales Volume (dollars) | C41: =C7 -> 0 | D41: =D7 -> 2920 | E41: =E7 -> 2920 | F41: =F7 -> 2920 | G41: =G7 -> 2920 | H41: =H7 -> 2500 | I41: =I7 -> 10785 | J41: =J7 -> 5785 | ... N41: =N7 -> 7190
A42: Accounts Receivable
A43: Bad Debt (end of month)
A44: Inventory on hand (eom)
A45: Accounts Payable (eom)
A46: Depreciation
A47: Owner draw accrued this month | C47: =Assumptions!$B$43 -> 5000 | D47: =Assumptions!$B$43 -> 5000 | E47: =Assumptions!$B$43 -> 5000 | F47: =Assumptions!$B$43 -> 5000 | G47: =Assumptions!$B$43 -> 5000 | H47: =Assumptions!$B$43 -> 5000 | I47: =Assumptions!$B$43 -> 5000 | J47: =Assumptions!$B$43 -> 5000 | ... N47: =Assumptions!$B$43 -> 5000
...

Sheet 2nd Year Projections
A1: Fiscal Year Begins | O1: Expense growth (year 2) | P1: 0.03 | Q1: applies to expense rows that copy year 1
A2: ='1st Year Projections'!N4 -> 46753
B3: Month 13 | C3: Month 14 | D3: Month 15 | E3: Month 16 | F3: Month 17 | G3: Month 18 | H3: Month 19 | I3: Month 20 | J3: Month 21 | K3: Month 22 | L3: Month 23 | M3: Month 24 | N3: YEARLY | P3: Percentages
A4: Revenue | B4: =A2 -> 46753 | C4: =DATE(YEAR(B4),MONTH(B4)+1,1) -> 46784 | D4: =DATE(YEAR(C4),MONTH(C4)+1,1) -> 46813 | E4: =DATE(YEAR(D4),MONTH(D4)+1,1) -> 46844 | F4: =DATE(YEAR(E4),MONTH(E4)+1,1) -> 46874 | G4: =DATE(YEAR(F4),MONTH(F4)+1,1) -> 46905 | H4: =DATE(YEAR(G4),MONTH(G4)+1,1) -> 46935 | I4: =DATE(YEAR(H4),MONTH(H4)+1,1) -> 46966 | J4: =DATE(YEAR(I4),MONTH(I4)+1,1) -> 46997 | ... N4: =DATE(YEAR(M4),MONTH(M4)+1,1) -> 47119 | O4: Assumptions. Please describe how figures were derived.
A5: ='1st Year Projections'!A5 -> Gathering tickets & Season Passes | B5: =Assumptions!N32 -> 6205 | C5: =Assumptions!O32 -> 6205 | D5: =Assumptions!P32 -> 6205 | E5: =Assumptions!Q32 -> 6205 | F5: =Assumptions!R32 -> 6205 | G5: =Assumptions!S32 -> 0 | H5: =Assumptions!T32 -> 8395 | I5: =Assumptions!U32 -> 8395 | ... M5: =Assumptions!Y32 -> 0 | N5: =SUM(B5:M5) -> 73000 | O5: SLC 50 & Ogden 35 players x 10 months; Provo 30 x 5 months; $73 blended
A6: ='1st Year Projections'!A6 -> Corporate private runs | B6: =Assumptions!N33 -> 5000 | C6: =Assumptions!O33 -> 5000 | D6: =Assumptions!P33 -> 5000 | E6: =Assumptions!Q33 -> 5000 | F6: =Assumptions!R33 -> 5000 | G6: =Assumptions!S33 -> 5000 | H6: =Assumptions!T33 -> 5000 | I6: =Assumptions!U33 -> 5000 | ... M6: =Assumptions!Y33 -> 5000 | N6: =SUM(B6:M6) -> 60000 | O6: 2 private runs per month
A7: ='1st Year Projections'!A7 -> Sponsorships | B7: =Assumptions!N34 -> 5000 | C7: =Assumptions!O34 -> 0 | D7: =Assumptions!P34 -> 5000 | E7: =Assumptions!Q34 -> 0 | F7: =Assumptions!R34 -> 0 | G7: =Assumptions!S34 -> 0 | H7: =Assumptions!T34 -> 10000 | I7: =Assumptions!U34 -> 10000 | ... M7: =Assumptions!Y34 -> 0 | N7: =SUM(B7:M7) -> 35000 | O7: Chapter sponsors + $10k flagship sponsor
A8: ='1st Year Projections'!A8 -> Flagship & Vanguard membership | B8: =Assumptions!N35 -> 5400 | C8: =Assumptions!O35 -> 1800 | D8: =Assumptions!P35 -> 1800 | E8: =Assumptions!Q35 -> 1080 | F8: =Assumptions!R35 -> 1080 | G8: =Assumptions!S35 -> 1080 | H8: =Assumptions!T35 -> 1080 | I8: =Assumptions!U35 -> 1080 | ... M8: =Assumptions!Y35 -> 1080 | N8: =SUM(B8:M8) -> 62220 | O8: Flagship (Championship + Explorer weekend): 60 players x $725 (Sep); Vanguard: 52 members x $360
A9: Total Revenue (Sales) | B9: =SUM(B5:B8) -> 21605 | C9: =SUM(C5:C8) -> 13005 | D9: =SUM(D5:D8) -> 18005 | E9: =SUM(E5:E8) -> 12285 | F9: =SUM(F5:F8) -> 12285 | G9: =SUM(G5:G8) -> 6080 | H9: =SUM(H5:H8) -> 24475 | I9: =SUM(I5:I8) -> 24475 | ... M9: =SUM(M5:M8) -> 6080 | N9: =SUM(B9:M9) -> 230220
A11: Cost of Goods Sold
A12: ='1st Year Projections'!A12 -> Gathering tickets & Season Passes (direct costs) | B12: =Assumptions!N37 -> 3400 | C12: =Assumptions!O37 -> 3400 | D12: =Assumptions!P37 -> 3400 | E12: =Assumptions!Q37 -> 3400 | F12: =Assumptions!R37 -> 3400 | G12: =Assumptions!S37 -> 0 | H12: =Assumptions!T37 -> 4600 | I12: =Assumptions!U37 -> 4600 | ... M12: =Assumptions!Y37 -> 0 | N12: =SUM(B12:M12) -> 40000 | P12: =IFERROR(N12/N5,"") -> 0.54794521
A13: ='1st Year Projections'!A13 -> Corporate private runs (direct costs) | B13: =Assumptions!N38 -> 2560 | C13: =Assumptions!O38 -> 2560 | D13: =Assumptions!P38 -> 2560 | E13: =Assumptions!Q38 -> 2560 | F13: =Assumptions!R38 -> 2560 | G13: =Assumptions!S38 -> 2560 | H13: =Assumptions!T38 -> 2560 | I13: =Assumptions!U38 -> 2560 | ... M13: =Assumptions!Y38 -> 2560 | N13: =SUM(B13:M13) -> 30720 | P13: =IFERROR(N13/N6,"") -> 0.512
A14: ='1st Year Projections'!A14 -> Sponsorships (direct costs) | B14: =Assumptions!N39 -> 500 | C14: =Assumptions!O39 -> 0 | D14: =Assumptions!P39 -> 500 | E14: =Assumptions!Q39 -> 0 | F14: =Assumptions!R39 -> 0 | G14: =Assumptions!S39 -> 0 | H14: =Assumptions!T39 -> 1000 | I14: =Assumptions!U39 -> 1000 | ... M14: =Assumptions!Y39 -> 0 | N14: =SUM(B14:M14) -> 3500 | P14: =IFERROR(N14/N7,"") -> 0.1
A15: ='1st Year Projections'!A15 -> Flagship & Vanguard membership (direct costs) | B15: =Assumptions!N40 -> 3375 | C15: =Assumptions!O40 -> 1125 | D15: =Assumptions!P40 -> 1125 | E15: =Assumptions!Q40 -> 675 | F15: =Assumptions!R40 -> 675 | G15: =Assumptions!S40 -> 675 | H15: =Assumptions!T40 -> 675 | I15: =Assumptions!U40 -> 675 | ... M15: =Assumptions!Y40 -> 675 | N15: =SUM(B15:M15) -> 44400 | P15: =IFERROR(N15/N8,"") -> 0.71359691
A16: Total Cost of Goods Sold | B16: =SUM(B12:B15) -> 9835 | C16: =SUM(C12:C15) -> 7085 | D16: =SUM(D12:D15) -> 7585 | E16: =SUM(E12:E15) -> 6635 | F16: =SUM(F12:F15) -> 6635 | G16: =SUM(G12:G15) -> 3235 | H16: =SUM(H12:H15) -> 8835 | I16: =SUM(I12:I15) -> 8835 | ... M16: =SUM(M12:M15) -> 3235 | N16: =SUM(B16:M16) -> 118620 | P16: =IFERROR(N16/N9, "") -> 0.51524629
A18: Gross Profit | B18: =B9-B16 -> 11770 | C18: =C9-C16 -> 5920 | D18: =D9-D16 -> 10420 | E18: =E9-E16 -> 5650 | F18: =F9-F16 -> 5650 | G18: =G9-G16 -> 2845 | H18: =H9-H16 -> 15640 | I18: =I9-I16 -> 15640 | ... N18: =N9-N16 -> 111600
A20: Expenses
A21: ='1st Year Projections'!A21 -> Marketing | B21: 1500 | C21: 1500 | D21: 1500 | E21: 1500 | F21: 1500 | G21: 1500 | H21: 1500 | I21: 1500 | J21: 1500 | K21: 1500 | L21: 1500 | M21: 1500 | N21: =SUM(B21:M21) -> 18000 | O21: $1,500/month across three chapters
A22: ='1st Year Projections'!A22 -> Bank Charges | B22: ='1st Year Projections'!B22*(1+$P$1) -> 20.6 | C22: ='1st Year Projections'!C22*(1+$P$1) -> 20.6 | D22: ='1st Year Projections'!D22*(1+$P$1) -> 20.6 | E22: ='1st Year Projections'!E22*(1+$P$1) -> 20.6 | F22: ='1st Year Projections'!F22*(1+$P$1) -> 20.6 | G22: ='1st Year Projections'!G22*(1+$P$1) -> 20.6 | H22: ='1st Year Projections'!H22*(1+$P$1) -> 20.6 | I22: ='1st Year Projections'!I22*(1+$P$1) -> 20.6 | ... M22: ='1st Year Projections'!M22*(1+$P$1) -> 20.6 | N22: =SUM(B22:M22) -> 247.2 | O22: Other rows: year 1 + 3%
A23: ='1st Year Projections'!A23 -> Car-Truck | B23: 200 | C23: 200 | D23: 200 | E23: 200 | F23: 200 | G23: 200 | H23: 200 | I23: 200 | J23: 200 | K23: 200 | L23: 200 | M23: 200 | N23: =SUM(B23:M23) -> 2400 | O23: Mileage across Salt Lake, Ogden, Provo
A24: ='1st Year Projections'!A24 -> Utilities | B24: ='1st Year Projections'!B24*(1+$P$1) -> 0 | C24: ='1st Year Projections'!C24*(1+$P$1) -> 0 | D24: ='1st Year Projections'!D24*(1+$P$1) -> 0 | E24: ='1st Year Projections'!E24*(1+$P$1) -> 0 | F24: ='1st Year Projections'!F24*(1+$P$1) -> 0 | G24: ='1st Year Projections'!G24*(1+$P$1) -> 0 | H24: ='1st Year Projections'!H24*(1+$P$1) -> 0 | I24: ='1st Year Projections'!I24*(1+$P$1) -> 0 | ... M24: ='1st Year Projections'!M24*(1+$P$1) -> 0 | N24: =SUM(B24:M24) -> 0
A25: ='1st Year Projections'!A25 -> Rent/Lease | B25: ='1st Year Projections'!B25*(1+$P$1) -> 77.25 | C25: ='1st Year Projections'!C25*(1+$P$1) -> 77.25 | D25: ='1st Year Projections'!D25*(1+$P$1) -> 77.25 | E25: ='1st Year Projections'!E25*(1+$P$1) -> 77.25 | F25: ='1st Year Projections'!F25*(1+$P$1) -> 77.25 | G25: ='1st Year Projections'!G25*(1+$P$1) -> 77.25 | H25: ='1st Year Projections'!H25*(1+$P$1) -> 77.25 | I25: ='1st Year Projections'!I25*(1+$P$1) -> 77.25 | ... M25: ='1st Year Projections'!M25*(1+$P$1) -> 77.25 | N25: =SUM(B25:M25) -> 927
A26: ='1st Year Projections'!A26 -> Merchant Service Fees | B26: =B9*Assumptions!$B$17 -> 324.075 | C26: =C9*Assumptions!$B$17 -> 195.075 | D26: =D9*Assumptions!$B$17 -> 270.075 | E26: =E9*Assumptions!$B$17 -> 184.275 | F26: =F9*Assumptions!$B$17 -> 184.275 | G26: =G9*Assumptions!$B$17 -> 91.2 | H26: =H9*Assumptions!$B$17 -> 367.125 | I26: =I9*Assumptions!$B$17 -> 367.125 | ... M26: =M9*Assumptions!$B$17 -> 91.2 | N26: =SUM(B26:M26) -> 3453.3
A27: ='1st Year Projections'!A27 -> Office & Supplies | B27: ='1st Year Projections'!B27*(1+$P$1) -> 103 | C27: ='1st Year Projections'!C27*(1+$P$1) -> 103 | D27: ='1st Year Projections'!D27*(1+$P$1) -> 103 | E27: ='1st Year Projections'!E27*(1+$P$1) -> 103 | F27: ='1st Year Projections'!F27*(1+$P$1) -> 103 | G27: ='1st Year Projections'!G27*(1+$P$1) -> 103 | H27: ='1st Year Projections'!H27*(1+$P$1) -> 103 | I27: ='1st Year Projections'!I27*(1+$P$1) -> 103 | ... M27: ='1st Year Projections'!M27*(1+$P$1) -> 103 | N27: =SUM(B27:M27) -> 1236
A28: ='1st Year Projections'!A28 -> Office Meals / Entertainment | B28: ='1st Year Projections'!B28*(1+$P$1) -> 77.25 | C28: ='1st Year Projections'!C28*(1+$P$1) -> 77.25 | D28: ='1st Year Projections'!D28*(1+$P$1) -> 77.25 | E28: ='1st Year Projections'!E28*(1+$P$1) -> 77.25 | F28: ='1st Year Projections'!F28*(1+$P$1) -> 77.25 | G28: ='1st Year Projections'!G28*(1+$P$1) -> 77.25 | H28: ='1st Year Projections'!H28*(1+$P$1) -> 77.25 | I28: ='1st Year Projections'!I28*(1+$P$1) -> 77.25 | ... M28: ='1st Year Projections'!M28*(1+$P$1) -> 77.25 | N28: =SUM(B28:M28) -> 927
A29: ='1st Year Projections'!A29 -> Repairs | B29: ='1st Year Projections'!B29*(1+$P$1) -> 0 | C29: ='1st Year Projections'!C29*(1+$P$1) -> 0 | D29: ='1st Year Projections'!D29*(1+$P$1) -> 0 | E29: ='1st Year Projections'!E29*(1+$P$1) -> 0 | F29: ='1st Year Projections'!F29*(1+$P$1) -> 0 | G29: ='1st Year Projections'!G29*(1+$P$1) -> 0 | H29: ='1st Year Projections'!H29*(1+$P$1) -> 0 | I29: ='1st Year Projections'!I29*(1+$P$1) -> 0 | ... M29: ='1st Year Projections'!M29*(1+$P$1) -> 0 | N29: =SUM(B29:M29) -> 0
A30: ='1st Year Projections'!A30 -> Salary Expenses | B30: 800 | C30: 800 | D30: 800 | E30: 800 | F30: 800 | G30: 800 | H30: 1600 | I30: 1600 | J30: 1600 | K30: 1600 | L30: 1600 | M30: 1600 | N30: =SUM(B30:M30) -> 14400 | O30: Ogden lead $800/mo; Provo lead $800/mo from Jul. Owner is paid by draw (Cash Flow tab), not salary
A31: ='1st Year Projections'!A31 -> Telephone & Internet | B31: ='1st Year Projections'!B31*(1+$P$1) -> 77.25 | C31: ='1st Year Projections'!C31*(1+$P$1) -> 77.25 | D31: ='1st Year Projections'!D31*(1+$P$1) -> 77.25 | E31: ='1st Year Projections'!E31*(1+$P$1) -> 77.25 | F31: ='1st Year Projections'!F31*(1+$P$1) -> 77.25 | G31: ='1st Year Projections'!G31*(1+$P$1) -> 77.25 | H31: ='1st Year Projections'!H31*(1+$P$1) -> 77.25 | I31: ='1st Year Projections'!I31*(1+$P$1) -> 77.25 | ... M31: ='1st Year Projections'!M31*(1+$P$1) -> 77.25 | N31: =SUM(B31:M31) -> 927
A32: ='1st Year Projections'!A32 -> Insurance | B32: ='1st Year Projections'!B32*(1+$P$1) -> 103 | C32: ='1st Year Projections'!C32*(1+$P$1) -> 103 | D32: ='1st Year Projections'!D32*(1+$P$1) -> 103 | E32: ='1st Year Projections'!E32*(1+$P$1) -> 103 | F32: ='1st Year Projections'!F32*(1+$P$1) -> 103 | G32: ='1st Year Projections'!G32*(1+$P$1) -> 103 | H32: ='1st Year Projections'!H32*(1+$P$1) -> 103 | I32: ='1st Year Projections'!I32*(1+$P$1) -> 103 | ... M32: ='1st Year Projections'!M32*(1+$P$1) -> 103 | N32: =SUM(B32:M32) -> 1236
A33: ='1st Year Projections'!A33 -> Interest Expense Loan #1 | B33: ='Proposed Loan Details'!G7 -> 104.71649 | C33: ='Proposed Loan Details'!H7 -> 102.93324 | D33: ='Proposed Loan Details'!I7 -> 101.13514 | E33: ='Proposed Loan Details'!J7 -> 99.32205 | F33: ='Proposed Loan Details'!K7 -> 97.493854 | G33: ='Proposed Loan Details'!L7 -> 95.650422 | H33: ='Proposed Loan Details'!M7 -> 93.791628 | I33: ='Proposed Loan Details'!N7 -> 91.917344 | ... M33: ='Proposed Loan Details'!R7 -> 84.262712 | N33: =SUM(B33:M33) -> 1135.5724 | O33: Year-2 interest on the $15,000 loan
A34: ='1st Year Projections'!A34 -> Interest Expense Loan #2 | B34: ='Proposed Loan Details'!G13 -> 0 | C34: ='Proposed Loan Details'!H13 -> 0 | D34: ='Proposed Loan Details'!I13 -> 0 | E34: ='Proposed Loan Details'!J13 -> 0 | F34: ='Proposed Loan Details'!K13 -> 0 | G34: ='Proposed Loan Details'!L13 -> 0 | H34: ='Proposed Loan Details'!M13 -> 0 | I34: ='Proposed Loan Details'!N13 -> 0 | ... M34: ='Proposed Loan Details'!R13 -> 0 | N34: =SUM(B34:M34) -> 0
A35: ='1st Year Projections'!A35 -> Software & Web Pass | B35: ='1st Year Projections'!B35*(1+$P$1) -> 123.6 | C35: ='1st Year Projections'!C35*(1+$P$1) -> 123.6 | D35: ='1st Year Projections'!D35*(1+$P$1) -> 123.6 | E35: ='1st Year Projections'!E35*(1+$P$1) -> 123.6 | F35: ='1st Year Projections'!F35*(1+$P$1) -> 123.6 | G35: ='1st Year Projections'!G35*(1+$P$1) -> 123.6 | H35: ='1st Year Projections'!H35*(1+$P$1) -> 123.6 | I35: ='1st Year Projections'!I35*(1+$P$1) -> 123.6 | ... M35: ='1st Year Projections'!M35*(1+$P$1) -> 123.6 | N35: =SUM(B35:M35) -> 1483.2
A36: ='1st Year Projections'!A36 -> Professional Fees (legal, trademark, CPA) | B36: ='1st Year Projections'!B36*(1+$P$1) -> 1545 | C36: ='1st Year Projections'!C36*(1+$P$1) -> 0 | D36: ='1st Year Projections'!D36*(1+$P$1) -> 1030 | E36: ='1st Year Projections'!E36*(1+$P$1) -> 103 | F36: ='1st Year Projections'!F36*(1+$P$1) -> 103 | G36: ='1st Year Projections'!G36*(1+$P$1) -> 103 | H36: ='1st Year Projections'!H36*(1+$P$1) -> 103 | I36: ='1st Year Projections'!I36*(1+$P$1) -> 103 | ... M36: ='1st Year Projections'!M36*(1+$P$1) -> 103 | N36: =SUM(B36:M36) -> 3502
A37: ='1st Year Projections'!A37 -> Licenses, Permits & Fees | B37: ='1st Year Projections'!B37*(1+$P$1) -> 51.5 | C37: ='1st Year Projections'!C37*(1+$P$1) -> 51.5 | D37: ='1st Year Projections'!D37*(1+$P$1) -> 51.5 | E37: ='1st Year Projections'!E37*(1+$P$1) -> 51.5 | F37: ='1st Year Projections'!F37*(1+$P$1) -> 51.5 | G37: ='1st Year Projections'!G37*(1+$P$1) -> 51.5 | H37: ='1st Year Projections'!H37*(1+$P$1) -> 51.5 | I37: ='1st Year Projections'!I37*(1+$P$1) -> 51.5 | ... M37: ='1st Year Projections'!M37*(1+$P$1) -> 51.5 | N37: =SUM(B37:M37) -> 618
A38: ='1st Year Projections'!A38 -> Brand & Design | B38: 0 | C38: 0 | D38: 0 | E38: 0 | F38: 0 | G38: 0 | H38: 0 | I38: 1500 | J38: 0 | K38: 0 | L38: 0 | M38: 0 | N38: =SUM(B38:M38) -> 1500 | O38: Flagship identity and Vanguard kit design
A39: Total Expenses | B39: =SUM(B21:B38) -> 5107.2415 | C39: =SUM(C21:C38) -> 3431.4582 | D39: =SUM(D21:D38) -> 4534.6601 | E39: =SUM(E21:E38) -> 3520.0471 | F39: =SUM(F21:F38) -> 3518.2189 | G39: =SUM(G21:G38) -> 3423.3004 | H39: =SUM(H21:H38) -> 4497.3666 | I39: =SUM(I21:I38) -> 5995.4923 | ... N39: =SUM(N21:N38) -> 51992.272
A41: Net Profit Before Taxes | B41: =B18-B39 -> 6662.7585 | C41: =C18-C39 -> 2488.5418 | D41: =D18-D39 -> 5885.3399 | E41: =E18-E39 -> 2129.9529 | F41: =F18-F39 -> 2131.7811 | G41: =G18-G39 -> -578.30042 | H41: =H18-H39 -> 11142.633 | I41: =I18-I39 -> 9644.5077 | ... N41: =N18-N39 -> 59607.728 | P41: =IFERROR(N41/N9,"") -> 0.25891637

Sheet 2nd Yr Summary
A1: Fiscal Year Begins
A2: ='1st Year Projections'!N4 -> 46753
B3: YEARLY | E3: Percentages
A4: Revenue | B4: Year 2 | D4: Assumptions. Please describe how figures were derived. | F4: Year 2 totals come straight from the 2nd Year Projections tab
A5: ='2nd Year Projections'!A5 -> Gathering tickets & Season Passes | B5: ='2nd Year Projections'!N5 -> 73000
A6: ='2nd Year Projections'!A6 -> Corporate private runs | B6: ='2nd Year Projections'!N6 -> 60000
A7: ='2nd Year Projections'!A7 -> Sponsorships | B7: ='2nd Year Projections'!N7 -> 35000
A8: ='2nd Year Projections'!A8 -> Flagship & Vanguard membership | B8: ='2nd Year Projections'!N8 -> 62220
A9: Total Revenue (Sales) | B9: =SUM(B5:B8) -> 230220
A11: Cost of Goods Sold
A12: ='2nd Year Projections'!A12 -> Gathering tickets & Season Passes (direct costs) | B12: ='2nd Year Projections'!N12 -> 40000
A13: ='2nd Year Projections'!A13 -> Corporate private runs (direct costs) | B13: ='2nd Year Projections'!N13 -> 30720
A14: ='2nd Year Projections'!A14 -> Sponsorships (direct costs) | B14: ='2nd Year Projections'!N14 -> 3500
A15: ='2nd Year Projections'!A15 -> Flagship & Vanguard membership (direct costs) | B15: ='2nd Year Projections'!N15 -> 44400
A16: Total Cost of Goods Sold | B16: =SUM(B12:B15) -> 118620 | E16: =IFERROR(B16/B9,"") -> 0.51524629
A18: Gross Profit | B18: =B9-B16 -> 111600 | E18: =B18/B9 -> 0.48475371
A20: Expenses
A21: ='2nd Year Projections'!A21 -> Marketing | B21: ='2nd Year Projections'!N21 -> 18000
A22: ='2nd Year Projections'!A22 -> Bank Charges | B22: ='2nd Year Projections'!N22 -> 247.2
A23: ='2nd Year Projections'!A23 -> Car-Truck | B23: ='2nd Year Projections'!N23 -> 2400
A24: ='2nd Year Projections'!A24 -> Utilities | B24: ='2nd Year Projections'!N24 -> 0
A25: ='2nd Year Projections'!A25 -> Rent/Lease | B25: ='2nd Year Projections'!N25 -> 927
A26: ='2nd Year Projections'!A26 -> Merchant Service Fees | B26: ='2nd Year Projections'!N26 -> 3453.3
A27: ='2nd Year Projections'!A27 -> Office & Supplies | B27: ='2nd Year Projections'!N27 -> 1236
A28: ='2nd Year Projections'!A28 -> Office Meals / Entertainment | B28: ='2nd Year Projections'!N28 -> 927
A29: ='2nd Year Projections'!A29 -> Repairs | B29: ='2nd Year Projections'!N29 -> 0
A30: ='2nd Year Projections'!A30 -> Salary Expenses | B30: ='2nd Year Projections'!N30 -> 14400
A31: ='2nd Year Projections'!A31 -> Telephone & Internet | B31: ='2nd Year Projections'!N31 -> 927
A32: ='2nd Year Projections'!A32 -> Insurance | B32: ='2nd Year Projections'!N32 -> 1236
... A38: ='2nd Year Projections'!A38 -> Brand & Design | B38: ='2nd Year Projections'!N38 -> 1500
A39: Total Expenses | B39: =SUM(B21:B38) -> 51992.272 | E39: =B39/B9 -> 0.22583734
A41: Net Profit Before Taxes | B41: =B18-B39 -> 59607.728 | E41: =IFERROR(B41/B9,"") -> 0.25891637

Sheet Cash Flow 2nd Year
A1: 12 Month Cash Flow Statement
A2: Cash Flow (12 months) | G2: ='1st Year Projections'!B1 -> Business Name: Colgrid | N2: Fiscal Year Begins: | O2: ='2nd Year Projections'!A2 -> 46753
B3: Pre-Startup EST | C3: =O2 -> 46753 | D3: =DATE(YEAR(C3),MONTH(C3)+1,1) -> 46784 | E3: =DATE(YEAR(D3),MONTH(D3)+1,1) -> 46813 | F3: =DATE(YEAR(E3),MONTH(E3)+1,1) -> 46844 | G3: =DATE(YEAR(F3),MONTH(F3)+1,1) -> 46874 | H3: =DATE(YEAR(G3),MONTH(G3)+1,1) -> 46905 | I3: =DATE(YEAR(H3),MONTH(H3)+1,1) -> 46935 | J3: =DATE(YEAR(I3),MONTH(I3)+1,1) -> 46966 | K3: =DATE(YEAR(J3),MONTH(J3)+1,1) -> 46997 | ... N3: =DATE(YEAR(M3),MONTH(M3)+1,1) -> 47088 | O3: Total Item EST
A4: Cash on Hand (beginning of month) | C4: ='Cash Flow 1st Year'!N38 -> 10000 | D4: =C38 -> 10000 | E4: =D38 -> 10000 | F4: =E38 -> 10000 | G4: =F38 -> 10000 | H4: =G38 -> 10000 | I4: =H38 -> 9198.6443 | J4: =I38 -> 10000 | K4: =J38 -> 10000 | ... N4: =M38 -> 10000 | O4: =C4 -> 10000
A6: CASH RECEIPTS
A7: Cash Sales | C7: ='2nd Year Projections'!B9 -> 21605 | D7: ='2nd Year Projections'!C9 -> 13005 | E7: ='2nd Year Projections'!D9 -> 18005 | F7: ='2nd Year Projections'!E9 -> 12285 | G7: ='2nd Year Projections'!F9 -> 12285 | H7: ='2nd Year Projections'!G9 -> 6080 | I7: ='2nd Year Projections'!H9 -> 24475 | J7: ='2nd Year Projections'!I9 -> 24475 | ... N7: ='2nd Year Projections'!M9 -> 6080 | O7: =SUM(C7:N7) -> 230220
A8: Collections fm CR accounts | O8: =SUM(C8:N8) -> 0
A9: Loan/ other cash inj. | O9: =SUM(C9:N9) -> 0
A10: TOTAL CASH RECEIPTS | B10: =SUM(B7:B9) -> 0 | C10: =SUM(C7:C9) -> 21605 | D10: =SUM(D7:D9) -> 13005 | E10: =SUM(E7:E9) -> 18005 | F10: =SUM(F7:F9) -> 12285 | G10: =SUM(G7:G9) -> 12285 | H10: =SUM(H7:H9) -> 6080 | I10: =SUM(I7:I9) -> 24475 | ... O10: =SUM(O7:O9) -> 230220
A11: Total Cash Available (before cash out) | B11: =(B4+B10) -> 0 | C11: =(C4+C10) -> 31605 | D11: =(D4+D10) -> 23005 | E11: =(E4+E10) -> 28005 | F11: =(F4+F10) -> 22285 | G11: =(G4+G10) -> 22285 | H11: =(H4+H10) -> 16080 | I11: =(I4+I10) -> 33673.644 | ... O11: =(O4+O10) -> 240220
A13: CASH PAID OUT
